GET / - 200
GET /static/css/index/button.css - 304
GET /static/css/style.css - 304
GET /static/css/index/Hero.css - 304
GET /static/css/index/services.css - 304
GET /static/css/index/latest.css - 304
GET /static/css/index/about.css - 304
GET /static/css/index/invite.css - 304
GET /static/css/index/footer.css - 304
GET /static/images/Logo/dark-blue-light.png - 304
GET /static/js/hamburger-menu.js - 304
GET /static/images/Unsplash/blue-bird.jpg - 304
GET /static/images/Logo/Light-purple.png - 304
GET /static/images/Unsplash/person-ocean.jpg - 304
GET /welcome_create_account - 200
GET /static/css/Account/Welcome-create-account.css - 304
GET /static/css/index/Hero.css - 304
GET /static/css/style.css - 304
GET /static/css/index/button.css - 304
GET /static/images/Logo/dark-blue-light.png - 304
GET /create_account_names - 200
GET /static/css/style.css - 304
GET /static/css/index/button.css - 304
GET /static/css/Account/create-account.css - 304
GET /static/css/Account/style.css - 404
GET /static/images/Logo/dark-blue-light.png - 304
GET /create_account_names - 200
GET /static/css/Account/create-account.css - 304
GET /static/css/style.css - 304
GET /static/css/index/button.css - 304
GET /static/css/Account/style.css - 404
GET /static/images/Logo/dark-blue-light.png - 304
GET /static/images/Favicon/Dark.png - 304
Exception on /save_event [POST]
Traceback (most recent call last):
  File "/home/sierra-95/.local/lib/python3.10/site-packages/flask/app.py", line 1455, in wsgi_app
    response = self.full_dispatch_request()
  File "/home/sierra-95/.local/lib/python3.10/site-packages/flask/app.py", line 869, in full_dispatch_request
    rv = self.handle_user_exception(e)
  File "/home/sierra-95/.local/lib/python3.10/site-packages/flask/app.py", line 867, in full_dispatch_request
    rv = self.dispatch_request()
  File "/home/sierra-95/.local/lib/python3.10/site-packages/flask/app.py", line 852, in dispatch_request
    return self.ensure_sync(self.view_functions[rule.endpoint])(**view_args)
  File "/home/sierra-95/Tomorrow/web-flask/app.py", line 189, in save_event
    execute_query(query, values)
  File "/home/sierra-95/Tomorrow/web-flask/app.py", line 38, in execute_query
    cursor = db.cursor()
  File "/home/sierra-95/.local/lib/python3.10/site-packages/mysql/connector/connection_cext.py", line 728, in cursor
    raise OperationalError("MySQL Connection not available.")
mysql.connector.errors.OperationalError: MySQL Connection not available.
Exception on /get_todays_events [GET]
Traceback (most recent call last):
  File "/home/sierra-95/.local/lib/python3.10/site-packages/flask/app.py", line 1455, in wsgi_app
    response = self.full_dispatch_request()
  File "/home/sierra-95/.local/lib/python3.10/site-packages/flask/app.py", line 869, in full_dispatch_request
    rv = self.handle_user_exception(e)
  File "/home/sierra-95/.local/lib/python3.10/site-packages/flask/app.py", line 867, in full_dispatch_request
    rv = self.dispatch_request()
  File "/home/sierra-95/.local/lib/python3.10/site-packages/flask/app.py", line 852, in dispatch_request
    return self.ensure_sync(self.view_functions[rule.endpoint])(**view_args)
  File "/home/sierra-95/Tomorrow/web-flask/app.py", line 217, in get_todays_events
    today = datetime.date.today()
AttributeError: 'method_descriptor' object has no attribute 'today'
Exception on /get_todays_events [GET]
Traceback (most recent call last):
  File "/home/sierra-95/.local/lib/python3.10/site-packages/flask/app.py", line 1455, in wsgi_app
    response = self.full_dispatch_request()
  File "/home/sierra-95/.local/lib/python3.10/site-packages/flask/app.py", line 869, in full_dispatch_request
    rv = self.handle_user_exception(e)
  File "/home/sierra-95/.local/lib/python3.10/site-packages/flask/app.py", line 867, in full_dispatch_request
    rv = self.dispatch_request()
  File "/home/sierra-95/.local/lib/python3.10/site-packages/flask/app.py", line 852, in dispatch_request
    return self.ensure_sync(self.view_functions[rule.endpoint])(**view_args)
  File "/home/sierra-95/Tomorrow/web-flask/app.py", line 217, in get_todays_events
    today = datetime.date.today()
AttributeError: 'method_descriptor' object has no attribute 'today'
Exception on /dashboard [GET]
Traceback (most recent call last):
  File "/home/sierra-95/.local/lib/python3.10/site-packages/flask/app.py", line 1455, in wsgi_app
    response = self.full_dispatch_request()
  File "/home/sierra-95/.local/lib/python3.10/site-packages/flask/app.py", line 869, in full_dispatch_request
    rv = self.handle_user_exception(e)
  File "/home/sierra-95/.local/lib/python3.10/site-packages/flask/app.py", line 867, in full_dispatch_request
    rv = self.dispatch_request()
  File "/home/sierra-95/.local/lib/python3.10/site-packages/flask/app.py", line 852, in dispatch_request
    return self.ensure_sync(self.view_functions[rule.endpoint])(**view_args)
  File "/home/sierra-95/Tomorrow/web-flask/app.py", line 187, in dashboard
    return render_template('dashboard.html', user_id=user_id)
  File "/home/sierra-95/.local/lib/python3.10/site-packages/flask/templating.py", line 151, in render_template
    template = app.jinja_env.get_or_select_template(template_name_or_list)
  File "/home/sierra-95/.local/lib/python3.10/site-packages/jinja2/environment.py", line 1081, in get_or_select_template
    return self.get_template(template_name_or_list, parent, globals)
  File "/home/sierra-95/.local/lib/python3.10/site-packages/jinja2/environment.py", line 1010, in get_template
    return self._load_template(name, globals)
  File "/home/sierra-95/.local/lib/python3.10/site-packages/jinja2/environment.py", line 969, in _load_template
    template = self.loader.load(self, name, self.make_globals(globals))
  File "/home/sierra-95/.local/lib/python3.10/site-packages/jinja2/loaders.py", line 126, in load
    source, filename, uptodate = self.get_source(environment, name)
  File "/home/sierra-95/.local/lib/python3.10/site-packages/flask/templating.py", line 65, in get_source
    return self._get_source_fast(environment, template)
  File "/home/sierra-95/.local/lib/python3.10/site-packages/flask/templating.py", line 99, in _get_source_fast
    raise TemplateNotFound(template)
jinja2.exceptions.TemplateNotFound: dashboard.html
Exception on /dashboard [GET]
Traceback (most recent call last):
  File "/home/sierra-95/.local/lib/python3.10/site-packages/flask/app.py", line 1455, in wsgi_app
    response = self.full_dispatch_request()
  File "/home/sierra-95/.local/lib/python3.10/site-packages/flask/app.py", line 869, in full_dispatch_request
    rv = self.handle_user_exception(e)
  File "/home/sierra-95/.local/lib/python3.10/site-packages/flask/app.py", line 867, in full_dispatch_request
    rv = self.dispatch_request()
  File "/home/sierra-95/.local/lib/python3.10/site-packages/flask/app.py", line 852, in dispatch_request
    return self.ensure_sync(self.view_functions[rule.endpoint])(**view_args)
  File "/home/sierra-95/Tomorrow/web-flask/app.py", line 187, in dashboard
    return render_template('index.html', user_id=user_id)
  File "/home/sierra-95/.local/lib/python3.10/site-packages/flask/templating.py", line 152, in render_template
    return _render(app, template, context)
  File "/home/sierra-95/.local/lib/python3.10/site-packages/flask/templating.py", line 133, in _render
    rv = template.render(context)
  File "/home/sierra-95/.local/lib/python3.10/site-packages/jinja2/environment.py", line 1301, in render
    self.environment.handle_exception()
  File "/home/sierra-95/.local/lib/python3.10/site-packages/jinja2/environment.py", line 936, in handle_exception
    raise rewrite_traceback_stack(source=source)
  File "/home/sierra-95/Tomorrow/web-flask/templates/index.html", line 44, in top-level template code
    <h1 class="Hero-title">Welcome {{ user['first_name'] }} {{ user['last_name'] }}</h1>
  File "/home/sierra-95/.local/lib/python3.10/site-packages/jinja2/environment.py", line 466, in getitem
    return obj[argument]
jinja2.exceptions.UndefinedError: 'user' is undefined
Exception on /dashboard [GET]
Traceback (most recent call last):
  File "/home/sierra-95/.local/lib/python3.10/site-packages/flask/app.py", line 1455, in wsgi_app
    response = self.full_dispatch_request()
  File "/home/sierra-95/.local/lib/python3.10/site-packages/flask/app.py", line 869, in full_dispatch_request
    rv = self.handle_user_exception(e)
  File "/home/sierra-95/.local/lib/python3.10/site-packages/flask/app.py", line 867, in full_dispatch_request
    rv = self.dispatch_request()
  File "/home/sierra-95/.local/lib/python3.10/site-packages/flask/app.py", line 852, in dispatch_request
    return self.ensure_sync(self.view_functions[rule.endpoint])(**view_args)
  File "/home/sierra-95/Tomorrow/web-flask/app.py", line 188, in dashboard
    user = fetch_user_data(user_id)
NameError: name 'fetch_user_data' is not defined
Exception on /dashboard [GET]
Traceback (most recent call last):
  File "/home/sierra-95/.local/lib/python3.10/site-packages/flask/app.py", line 1455, in wsgi_app
    response = self.full_dispatch_request()
  File "/home/sierra-95/.local/lib/python3.10/site-packages/flask/app.py", line 869, in full_dispatch_request
    rv = self.handle_user_exception(e)
  File "/home/sierra-95/.local/lib/python3.10/site-packages/flask/app.py", line 867, in full_dispatch_request
    rv = self.dispatch_request()
  File "/home/sierra-95/.local/lib/python3.10/site-packages/flask/app.py", line 852, in dispatch_request
    return self.ensure_sync(self.view_functions[rule.endpoint])(**view_args)
  File "/home/sierra-95/Tomorrow/web-flask/app.py", line 217, in dashboard
    return render_template('index.html', user=user, events=events)
  File "/home/sierra-95/.local/lib/python3.10/site-packages/flask/templating.py", line 152, in render_template
    return _render(app, template, context)
  File "/home/sierra-95/.local/lib/python3.10/site-packages/flask/templating.py", line 133, in _render
    rv = template.render(context)
  File "/home/sierra-95/.local/lib/python3.10/site-packages/jinja2/environment.py", line 1301, in render
    self.environment.handle_exception()
  File "/home/sierra-95/.local/lib/python3.10/site-packages/jinja2/environment.py", line 936, in handle_exception
    raise rewrite_traceback_stack(source=source)
  File "/home/sierra-95/Tomorrow/web-flask/templates/index.html", line 33, in top-level template code
    <li><a href="{{ url_for('my_account') }}">My Account<span></span></a></li>
  File "/home/sierra-95/.local/lib/python3.10/site-packages/flask/app.py", line 1071, in url_for
    return self.handle_url_build_error(error, endpoint, values)
  File "/home/sierra-95/.local/lib/python3.10/site-packages/flask/app.py", line 1060, in url_for
    rv = url_adapter.build(  # type: ignore[union-attr]
  File "/home/sierra-95/.local/lib/python3.10/site-packages/werkzeug/routing/map.py", line 919, in build
    raise BuildError(endpoint, values, method, self)
werkzeug.routing.exceptions.BuildError: Could not build url for endpoint 'my_account'. Did you mean 'login_account' instead?
